...........................................................................Exception in thread Thread-123:
Traceback (most recent call last):
  File "/usr/lib64/python3.6/threading.py", line 916, in _bootstrap_inner
    self.run()
  File "/homes/lukepenney/Networking/csci357-rdt/exthread.py", line 15, in run
    super().run(*args, **kwargs)
  File "/usr/lib64/python3.6/threading.py", line 864, in run
    self._target(*self._args, **self._kwargs)
  File "./test_rdt.py", line 288, in client_stress
    'in chunk starting with byte {}'.format(count))
  File "/usr/lib64/python3.6/unittest/case.py", line 846, in assertEqual
    assertion_func(first, second, msg=msg)
  File "/usr/lib64/python3.6/unittest/case.py", line 839, in _baseAssertEqual
    raise self.failureException(msg)
AssertionError: b'567890123456789012345' != b'012345678901234567890' : in chunk starting with byte 783880

F
======================================================================
FAIL: test_07_stress (__main__.C1_Corrupt05_1x1)
A lot of data can be sent and received
----------------------------------------------------------------------
Traceback (most recent call last):
  File "./test_rdt.py", line 306, in test_07_stress
    self.c['c'].send(data[ofs:ofs+b])
  File "/homes/lukepenney/Networking/csci357-rdt/exthread.py", line 10, in __exit__
    self.join()
  File "/homes/lukepenney/Networking/csci357-rdt/exthread.py", line 22, in join
    assert not self._exc, 'failure in subthread'
AssertionError: failure in subthread

----------------------------------------------------------------------
Ran 76 tests in 246.423s

FAILED (failures=1)
